<?xml version="1.0" ?>
<!-- =================================================================================== -->
<!-- |    This document was autogenerated by xacro from robot.xacro                    | -->
<!-- |    EDITING THIS FILE BY HAND IS NOT RECOMMENDED                                 | -->
<!-- =================================================================================== -->
<robot name="bupt_dog">
  <material name="black">
    <color rgba="0.0 0.0 0.0 1.0"/>
  </material>
  <material name="blue">
    <color rgba="0.0 0.0 0.8 1.0"/>
  </material>
  <material name="green">
    <color rgba="0.0 0.8 0.0 1.0"/>
  </material>
  <material name="grey">
    <color rgba="0.2 0.2 0.2 1.0"/>
  </material>
  <material name="silver">
    <color rgba="0.9137254901960784 0.9137254901960784 0.8470588235294118 1.0"/>
  </material>
  <material name="orange">
    <color rgba="1.0 0.4235294117647059 0.0392156862745098 1.0"/>
  </material>
  <material name="brown">
    <color rgba="0.8705882352941177 0.8117647058823529 0.7647058823529411 1.0"/>
  </material>
  <material name="red">
    <color rgba="0.8 0.0 0.0 1.0"/>
  </material>
  <material name="white">
    <color rgba="1.0 1.0 1.0 1.0"/>
  </material>
  <link name="base_link"/>
  <joint name="base" type="fixed">
    <parent link="base_link"/>
    <child link="body"/>
  </joint>
  <link name="body">
    <visual>
      <origin rpy="0 0 0" xyz="0.0 0.0 0.0075"/>
      <geometry>
        <box size="0.322 0.22 0.115"/>
      </geometry>
      <material name="black"/>
    </visual>
    <collision>
      <origin rpy="0 0 0" xyz="0.0 0.0 0.0075"/>
      <geometry>
        <box size="0.322 0.22 0.115"/>
      </geometry>
    </collision>
    <inertial>
      <origin rpy="0 0 0" xyz="0.0054 -0.0012 0.0045"/>
      <mass value="7.1"/>
      <inertia ixx="0.0386" ixy="-0.0002" ixz="0.0006" iyy="0.0952" iyz="0.0002" izz="0.1153"/>
    </inertial>
  </link>
  <joint name="FL_X_joint" type="revolute">
    <origin rpy="0 0 0" xyz="0.222 0.048 0"/>
    <parent link="body"/>
    <child link="FL_X"/>
    <axis xyz="1 0 0"/>
    <limit effort="33.5" lower="-0.6981317007977318" upper="0.6981317007977318" velocity="21"/>
  </joint>
  <link name="FL_X">
    <visual>
      <origin rpy="1.5707963267948966 0.0 0.0" xyz="0.0 0.044305 0.0"/>
      <geometry>
        <cylinder length="0.08861" radius="0.046"/>
      </geometry>
      <material name="grey"/>
    </visual>
    <collision>
      <origin rpy="1.5707963267948966 0.0 0.0" xyz="0.0 0.044305 0.0"/>
      <geometry>
        <cylinder length="0.08861" radius="0.046"/>
      </geometry>
    </collision>
    <inertial>
      <origin rpy="0 0 0" xyz="-0.00239495 0.03437314 -0.00054552"/>
      <mass value="1.464"/>
      <inertia ixx="0.00217217" ixy="0.00188053" ixz="-1.47e-06" iyy="0.0021" iyz="-4.63e-06" izz="0.00238268"/>
    </inertial>
  </link>
  <joint name="FL_Y_joint" type="revolute">
    <origin rpy="0.0 0.0 0.0" xyz="0.0 0.08861 0.0"/>
    <parent link="FL_X"/>
    <child link="FL_Y"/>
    <axis xyz="0 1 0"/>
    <limit effort="33.5" lower="-0.17453292519943295" upper="2.0943951023931953" velocity="21"/>
  </joint>
  <link name="FL_Y">
    <visual>
      <origin rpy="0.0 0.0 0.0" xyz="0.0 0.0 -0.09"/>
      <geometry>
        <box size="0.044 0.033 0.18"/>
      </geometry>
      <material name="white"/>
    </visual>
    <collision>
      <origin rpy="0.0 0.0 0.0" xyz="0.0 0.0 -0.09"/>
      <geometry>
        <box size="0.044 0.033 0.18"/>
      </geometry>
    </collision>
    <inertial>
      <origin rpy="0 0 0" xyz="-0.00212211 -0.00384371 -0.06050698"/>
      <mass value="0.24385482"/>
      <inertia ixx="0.00113247" ixy="-2.7e-06" ixz="1.15e-05" iyy="0.0011627" iyz="3.51e-06" izz="9.535e-05"/>
    </inertial>
  </link>
  <joint name="FL_KNEE_joint" type="revolute">
    <origin rpy="0.0 0.0 0.0" xyz="0.0 0.0 -0.18"/>
    <parent link="FL_Y"/>
    <child link="FL_KNEE"/>
    <axis xyz="0 1 0"/>
    <limit effort="33.5" lower="-2.792526803190927" upper="-0.6108652381980153" velocity="21"/>
  </joint>
  <link name="FL_KNEE">
    <visual>
      <origin rpy="0.0 0.0 0.0" xyz="0.0 0.0 -0.09"/>
      <geometry>
        <box size="0.02977 0.0225 0.18"/>
      </geometry>
      <material name="white"/>
    </visual>
    <collision>
      <origin rpy="0.0 0.0 0.0" xyz="0.0 0.0 -0.09"/>
      <geometry>
        <box size="0.02977 0.0225 0.18"/>
      </geometry>
    </collision>
    <inertial>
      <origin rpy="0 0 0" xyz="0.00724726 0.00053374 -0.07371072"/>
      <mass value="0.14294956"/>
      <inertia ixx="0.00069629" ixy="-5.5e-07" ixz="-1.936e-05" iyy="0.00070451" iyz="5.62e-06" izz="1.808e-05"/>
    </inertial>
  </link>
  <joint name="FL_FOOT_joint" type="fixed">
    <origin rpy="0.0 0.0 0.0" xyz="0.0 0.0 -0.18"/>
    <parent link="FL_KNEE"/>
    <child link="FL_FOOT"/>
  </joint>
  <link name="FL_FOOT">
    <visual>
      <origin rpy="0 0 0" xyz="0 0 0"/>
      <geometry>
        <sphere radius="0.02144"/>
      </geometry>
      <material name="white"/>
    </visual>
    <collision>
      <origin rpy="0 0 0" xyz="0 0 0"/>
      <geometry>
        <sphere radius="0.02144"/>
      </geometry>
    </collision>
    <inertial>
      <origin rpy="0 0 0" xyz="-0.00208901 0.0 -0.00361864"/>
      <mass value="0.009"/>
      <inertia ixx="1.22e-06" ixy="0.0" ixz="-1.3e-07" iyy="6.6e-07" iyz="0.0" izz="1.36e-06"/>
    </inertial>
  </link>
  <joint name="FR_X_joint" type="revolute">
    <origin rpy="0 0 0" xyz="0.222 -0.048 0"/>
    <parent link="body"/>
    <child link="FR_X"/>
    <axis xyz="1 0 0"/>
    <limit effort="33.5" lower="-0.6981317007977318" upper="0.6981317007977318" velocity="21"/>
  </joint>
  <link name="FR_X">
    <visual>
      <origin rpy="1.5707963267948966 0.0 0.0" xyz="0.0 -0.044305 0.0"/>
      <geometry>
        <cylinder length="0.08861" radius="0.046"/>
      </geometry>
      <material name="grey"/>
    </visual>
    <collision>
      <origin rpy="1.5707963267948966 0.0 0.0" xyz="0.0 -0.044305 0.0"/>
      <geometry>
        <cylinder length="0.08861" radius="0.046"/>
      </geometry>
    </collision>
    <inertial>
      <origin rpy="0 0 0" xyz="-0.00239495 -0.03437314 -0.00054552"/>
      <mass value="1.464"/>
      <inertia ixx="0.00217217" ixy="0.00188053" ixz="-1.47e-06" iyy="0.0021" iyz="-4.63e-06" izz="0.00238268"/>
    </inertial>
  </link>
  <joint name="FR_Y_joint" type="revolute">
    <origin rpy="0.0 0.0 0.0" xyz="0.0 -0.08861 0.0"/>
    <parent link="FR_X"/>
    <child link="FR_Y"/>
    <axis xyz="0 1 0"/>
    <limit effort="33.5" lower="-0.17453292519943295" upper="2.0943951023931953" velocity="21"/>
  </joint>
  <link name="FR_Y">
    <visual>
      <origin rpy="0.0 0.0 0.0" xyz="0.0 0.0 -0.09"/>
      <geometry>
        <box size="0.044 0.033 0.18"/>
      </geometry>
      <material name="white"/>
    </visual>
    <collision>
      <origin rpy="0.0 0.0 0.0" xyz="0.0 0.0 -0.09"/>
      <geometry>
        <box size="0.044 0.033 0.18"/>
      </geometry>
    </collision>
    <inertial>
      <origin rpy="0 0 0" xyz="-0.00212211 0.00384371 -0.06050698"/>
      <mass value="0.24385482"/>
      <inertia ixx="0.00113247" ixy="-2.7e-06" ixz="1.15e-05" iyy="0.0011627" iyz="3.51e-06" izz="9.535e-05"/>
    </inertial>
  </link>
  <joint name="FR_KNEE_joint" type="revolute">
    <origin rpy="0.0 0.0 0.0" xyz="0.0 0.0 -0.18"/>
    <parent link="FR_Y"/>
    <child link="FR_KNEE"/>
    <axis xyz="0 1 0"/>
    <limit effort="33.5" lower="-2.792526803190927" upper="-0.6108652381980153" velocity="21"/>
  </joint>
  <link name="FR_KNEE">
    <visual>
      <origin rpy="0.0 0.0 0.0" xyz="0.0 0.0 -0.09"/>
      <geometry>
        <box size="0.02977 0.0225 0.18"/>
      </geometry>
      <material name="white"/>
    </visual>
    <collision>
      <origin rpy="0.0 0.0 0.0" xyz="0.0 0.0 -0.09"/>
      <geometry>
        <box size="0.02977 0.0225 0.18"/>
      </geometry>
    </collision>
    <inertial>
      <origin rpy="0 0 0" xyz="0.00724726 0.00053374 -0.07371072"/>
      <mass value="0.14294956"/>
      <inertia ixx="0.00069629" ixy="-5.5e-07" ixz="-1.936e-05" iyy="0.00070451" iyz="5.62e-06" izz="1.808e-05"/>
    </inertial>
  </link>
  <joint name="FR_FOOT_joint" type="fixed">
    <origin rpy="0.0 0.0 0.0" xyz="0.0 0.0 -0.18"/>
    <parent link="FR_KNEE"/>
    <child link="FR_FOOT"/>
  </joint>
  <link name="FR_FOOT">
    <visual>
      <origin rpy="0 0 0" xyz="0 0 0"/>
      <geometry>
        <sphere radius="0.02144"/>
      </geometry>
      <material name="white"/>
    </visual>
    <collision>
      <origin rpy="0 0 0" xyz="0 0 0"/>
      <geometry>
        <sphere radius="0.02144"/>
      </geometry>
    </collision>
    <inertial>
      <origin rpy="0 0 0" xyz="-0.00208901 0.0 -0.00361864"/>
      <mass value="0.009"/>
      <inertia ixx="1.22e-06" ixy="0.0" ixz="-1.3e-07" iyy="6.6e-07" iyz="0.0" izz="1.36e-06"/>
    </inertial>
  </link>
  <joint name="HL_X_joint" type="revolute">
    <origin rpy="0 0 0" xyz="-0.222 0.048 0"/>
    <parent link="body"/>
    <child link="HL_X"/>
    <axis xyz="1 0 0"/>
    <limit effort="33.5" lower="-0.6981317007977318" upper="0.6981317007977318" velocity="21"/>
  </joint>
  <link name="HL_X">
    <visual>
      <origin rpy="1.5707963267948966 0.0 0.0" xyz="0.0 0.044305 0.0"/>
      <geometry>
        <cylinder length="0.08861" radius="0.046"/>
      </geometry>
      <material name="grey"/>
    </visual>
    <collision>
      <origin rpy="1.5707963267948966 0.0 0.0" xyz="0.0 0.044305 0.0"/>
      <geometry>
        <cylinder length="0.08861" radius="0.046"/>
      </geometry>
    </collision>
    <inertial>
      <origin rpy="0 0 0" xyz="0.00239495 0.03437314 -0.00054552"/>
      <mass value="1.464"/>
      <inertia ixx="0.00217217" ixy="0.00188053" ixz="-1.47e-06" iyy="0.0021" iyz="-4.63e-06" izz="0.00238268"/>
    </inertial>
  </link>
  <joint name="HL_Y_joint" type="revolute">
    <origin rpy="0.0 0.0 0.0" xyz="0.0 0.08861 0.0"/>
    <parent link="HL_X"/>
    <child link="HL_Y"/>
    <axis xyz="0 1 0"/>
    <limit effort="33.5" lower="-0.17453292519943295" upper="2.0943951023931953" velocity="21"/>
  </joint>
  <link name="HL_Y">
    <visual>
      <origin rpy="0.0 0.0 0.0" xyz="0.0 0.0 -0.09"/>
      <geometry>
        <box size="0.044 0.033 0.18"/>
      </geometry>
      <material name="white"/>
    </visual>
    <collision>
      <origin rpy="0.0 0.0 0.0" xyz="0.0 0.0 -0.09"/>
      <geometry>
        <box size="0.044 0.033 0.18"/>
      </geometry>
    </collision>
    <inertial>
      <origin rpy="0 0 0" xyz="-0.00212211 -0.00384371 -0.06050698"/>
      <mass value="0.24385482"/>
      <inertia ixx="0.00113247" ixy="-2.7e-06" ixz="1.15e-05" iyy="0.0011627" iyz="3.51e-06" izz="9.535e-05"/>
    </inertial>
  </link>
  <joint name="HL_KNEE_joint" type="revolute">
    <origin rpy="0.0 0.0 0.0" xyz="0.0 0.0 -0.18"/>
    <parent link="HL_Y"/>
    <child link="HL_KNEE"/>
    <axis xyz="0 1 0"/>
    <limit effort="33.5" lower="-2.792526803190927" upper="-0.6108652381980153" velocity="21"/>
  </joint>
  <link name="HL_KNEE">
    <visual>
      <origin rpy="0.0 0.0 0.0" xyz="0.0 0.0 -0.09"/>
      <geometry>
        <box size="0.02977 0.0225 0.18"/>
      </geometry>
      <material name="white"/>
    </visual>
    <collision>
      <origin rpy="0.0 0.0 0.0" xyz="0.0 0.0 -0.09"/>
      <geometry>
        <box size="0.02977 0.0225 0.18"/>
      </geometry>
    </collision>
    <inertial>
      <origin rpy="0 0 0" xyz="0.00724726 0.00053374 -0.07371072"/>
      <mass value="0.14294956"/>
      <inertia ixx="0.00069629" ixy="-5.5e-07" ixz="-1.936e-05" iyy="0.00070451" iyz="5.62e-06" izz="1.808e-05"/>
    </inertial>
  </link>
  <joint name="HL_FOOT_joint" type="fixed">
    <origin rpy="0.0 0.0 0.0" xyz="0.0 0.0 -0.18"/>
    <parent link="HL_KNEE"/>
    <child link="HL_FOOT"/>
  </joint>
  <link name="HL_FOOT">
    <visual>
      <origin rpy="0 0 0" xyz="0 0 0"/>
      <geometry>
        <sphere radius="0.02144"/>
      </geometry>
      <material name="white"/>
    </visual>
    <collision>
      <origin rpy="0 0 0" xyz="0 0 0"/>
      <geometry>
        <sphere radius="0.02144"/>
      </geometry>
    </collision>
    <inertial>
      <origin rpy="0 0 0" xyz="-0.00208901 0.0 -0.00361864"/>
      <mass value="0.009"/>
      <inertia ixx="1.22e-06" ixy="0.0" ixz="-1.3e-07" iyy="6.6e-07" iyz="0.0" izz="1.36e-06"/>
    </inertial>
  </link>
  <joint name="HR_X_joint" type="revolute">
    <origin rpy="0 0 0" xyz="-0.222 -0.048 0"/>
    <parent link="body"/>
    <child link="HR_X"/>
    <axis xyz="1 0 0"/>
    <limit effort="33.5" lower="-0.6981317007977318" upper="0.6981317007977318" velocity="21"/>
  </joint>
  <link name="HR_X">
    <visual>
      <origin rpy="1.5707963267948966 0.0 0.0" xyz="0.0 -0.044305 0.0"/>
      <geometry>
        <cylinder length="0.08861" radius="0.046"/>
      </geometry>
      <material name="grey"/>
    </visual>
    <collision>
      <origin rpy="1.5707963267948966 0.0 0.0" xyz="0.0 -0.044305 0.0"/>
      <geometry>
        <cylinder length="0.08861" radius="0.046"/>
      </geometry>
    </collision>
    <inertial>
      <origin rpy="0 0 0" xyz="0.00239495 -0.03437314 -0.00054552"/>
      <mass value="1.464"/>
      <inertia ixx="0.00217217" ixy="0.00188053" ixz="-1.47e-06" iyy="0.0021" iyz="-4.63e-06" izz="0.00238268"/>
    </inertial>
  </link>
  <joint name="HR_Y_joint" type="revolute">
    <origin rpy="0.0 0.0 0.0" xyz="0.0 -0.08861 0.0"/>
    <parent link="HR_X"/>
    <child link="HR_Y"/>
    <axis xyz="0 1 0"/>
    <limit effort="33.5" lower="-0.17453292519943295" upper="2.0943951023931953" velocity="21"/>
  </joint>
  <link name="HR_Y">
    <visual>
      <origin rpy="0.0 0.0 0.0" xyz="0.0 0.0 -0.09"/>
      <geometry>
        <box size="0.044 0.033 0.18"/>
      </geometry>
      <material name="white"/>
    </visual>
    <collision>
      <origin rpy="0.0 0.0 0.0" xyz="0.0 0.0 -0.09"/>
      <geometry>
        <box size="0.044 0.033 0.18"/>
      </geometry>
    </collision>
    <inertial>
      <origin rpy="0 0 0" xyz="-0.00212211 0.00384371 -0.06050698"/>
      <mass value="0.24385482"/>
      <inertia ixx="0.00113247" ixy="-2.7e-06" ixz="1.15e-05" iyy="0.0011627" iyz="3.51e-06" izz="9.535e-05"/>
    </inertial>
  </link>
  <joint name="HR_KNEE_joint" type="revolute">
    <origin rpy="0.0 0.0 0.0" xyz="0.0 0.0 -0.18"/>
    <parent link="HR_Y"/>
    <child link="HR_KNEE"/>
    <axis xyz="0 1 0"/>
    <limit effort="33.5" lower="-2.792526803190927" upper="-0.6108652381980153" velocity="21"/>
  </joint>
  <link name="HR_KNEE">
    <visual>
      <origin rpy="0.0 0.0 0.0" xyz="0.0 0.0 -0.09"/>
      <geometry>
        <box size="0.02977 0.0225 0.18"/>
      </geometry>
      <material name="white"/>
    </visual>
    <collision>
      <origin rpy="0.0 0.0 0.0" xyz="0.0 0.0 -0.09"/>
      <geometry>
        <box size="0.02977 0.0225 0.18"/>
      </geometry>
    </collision>
    <inertial>
      <origin rpy="0 0 0" xyz="0.00724726 0.00053374 -0.07371072"/>
      <mass value="0.14294956"/>
      <inertia ixx="0.00069629" ixy="-5.5e-07" ixz="-1.936e-05" iyy="0.00070451" iyz="5.62e-06" izz="1.808e-05"/>
    </inertial>
  </link>
  <joint name="HR_FOOT_joint" type="fixed">
    <origin rpy="0.0 0.0 0.0" xyz="0.0 0.0 -0.18"/>
    <parent link="HR_KNEE"/>
    <child link="HR_FOOT"/>
  </joint>
  <link name="HR_FOOT">
    <visual>
      <origin rpy="0 0 0" xyz="0 0 0"/>
      <geometry>
        <sphere radius="0.02144"/>
      </geometry>
      <material name="white"/>
    </visual>
    <collision>
      <origin rpy="0 0 0" xyz="0 0 0"/>
      <geometry>
        <sphere radius="0.02144"/>
      </geometry>
    </collision>
    <inertial>
      <origin rpy="0 0 0" xyz="-0.00208901 0.0 -0.00361864"/>
      <mass value="0.009"/>
      <inertia ixx="1.22e-06" ixy="0.0" ixz="-1.3e-07" iyy="6.6e-07" iyz="0.0" izz="1.36e-06"/>
    </inertial>
  </link>
</robot>

